Workbook
Name _GoBack: Recordings!#REF!

Sheet Recordings
A1: Text | B1: Next | C1: Campaign | D1: Speaker | E1: Subject | F1: Date | G1: Length | H1: Status_Final | I1: Access_audio | J1: Access_transcription | K1: Transcription_progress | L1: Status | M1: Rec. person | N1: transcribed by | O1: transcription checked by | P1: transcription checked by2 | Q1: translated by | R1: translation checked by | S1: glossed by | T1: glossing checked by | U1: Place | V1: Original Recording file | W1: Transcribed Audio-file | X1: Internal Procedural Notes | Y1: Document Type | Z1: Trigger_Warning | AA1: Title
A2: SAU_2022_Speaker10_marriage_1 | B2: SAU_2022_Speaker10_marriage_2 | C2: Saudi Arabia Fieldwork Campaign Gunda Kinzl 2022 | D2: {=_xlfn.TEXTJOIN(", ", TRUE(), _xlfn._xlws.FILTER(Speakers_in_Recordings!$B$2:$B$1502,Speakers_in_Recordings!$A$2:$A$1502=Rcrdngs[[#This Row],[Text]],"[no speaker selected in Speakers_in_Recordings]"))} -> SAU_2022_Speaker10, SAU_2022_Gunda | E2: {=_xlfn.TEXTJOIN(", ", TRUE(), _xlfn._xlws.FILTER(Sbcts_Rcrdngs[Subject],Sbcts_Rcrdngs[Recording]=Rcrdngs[[#This Row],[Text]],"[no subject selected in Subjects_in_Recordings]"))} -> Marriage | F2: 44633 | G2: 01:08 | H2: audio_transcription | I2: restricted | J2: restricted | K2: work in progress | L2: transcribed | M2: Gunda Kinzl | N2: Maria Rebecca Zarb | U2: Ha'il | X2: IMPORTANT: Speaker was ensured that the audio will only be used by the project, therefore it cannot be made public!!! | Y2: Free Speech | AA2: Saudi Arabia 2022 – Speaker 10 – Marriage (Part 1)
A3: SAU_2022_Speaker10_marriage_2 | C3: Saudi Arabia Fieldwork Campaign Gunda Kinzl 2022 | D3: {=_xlfn.TEXTJOIN(", ", TRUE(), _xlfn._xlws.FILTER(Speakers_in_Recordings!$B$2:$B$1502,Speakers_in_Recordings!$A$2:$A$1502=Rcrdngs[[#This Row],[Text]],"[no speaker selected in Speakers_in_Recordings]"))} -> SAU_2022_Speaker10, SAU_2022_Gunda | E3: {=_xlfn.TEXTJOIN(", ", TRUE(), _xlfn._xlws.FILTER(Sbcts_Rcrdngs[Subject],Sbcts_Rcrdngs[Recording]=Rcrdngs[[#This Row],[Text]],"[no subject selected in Subjects_in_Recordings]"))} -> Marriage, Feasts, Funerals | F3: 44605 | G3: 17:50 | H3: audio_transcription | I3: restricted | J3: restricted | K3: work in progress | L3: transcribed | M3: Gunda Kinzl | N3: Maria Rebecca Zarb | U3: Ha'il | X3: note for rebecca: purple means the transcription will be changed to public once corrected, red means it will stay restricted even when corrected due to sensitive info | Y3: Free Speech | AA3: Saudi Arabia 2022 – Speaker 10 – Marriage (Part 2)
A4: SAU_2022_Speaker20_traditionaltools | C4: Saudi Arabia Fieldwork Campaign Gunda Kinzl 2022 | D4: {=_xlfn.TEXTJOIN(", ", TRUE(), _xlfn._xlws.FILTER(Speakers_in_Recordings!$B$2:$B$1502,Speakers_in_Recordings!$A$2:$A$1502=Rcrdngs[[#This Row],[Text]],"[no speaker selected in Speakers_in_Recordings]"))} -> SAU_2022_Speaker20, SAU_2022_Speaker9, SAU_2022_CulturalInformant | E4: {=_xlfn.TEXTJOIN(", ", TRUE(), _xlfn._xlws.FILTER(Sbcts_Rcrdngs[Subject],Sbcts_Rcrdngs[Recording]=Rcrdngs[[#This Row],[Text]],"[no subject selected in Subjects_in_Recordings]"))} -> Tools | F4: 44635 | G4: 10:36 | H4: audio_transcription | I4: public | J4: restricted | K4: work in progress | L4: transcribed | M4: Gunda Kinzl | N4: Maria Rebecca Zarb | Y4: Free Speech | AA4: Saudi Arabia 2022 – Speaker 20 – Traditional Tools
A5: SAU_2022_Speaker20_shepherd | C5: Saudi Arabia Fieldwork Campaign Gunda Kinzl 2022 | D5: {=_xlfn.TEXTJOIN(", ", TRUE(), _xlfn._xlws.FILTER(Speakers_in_Recordings!$B$2:$B$1502,Speakers_in_Recordings!$A$2:$A$1502=Rcrdngs[[#This Row],[Text]],"[no speaker selected in Speakers_in_Recordings]"))} -> SAU_2022_Speaker20 | E5: {=_xlfn.TEXTJOIN(", ", TRUE(), _xlfn._xlws.FILTER(Sbcts_Rcrdngs[Subject],Sbcts_Rcrdngs[Recording]=Rcrdngs[[#This Row],[Text]],"[no subject selected in Subjects_in_Recordings]"))} -> Herding | F5: 44609 | G5: 05:30 | H5: audio_transcription | I5: public | J5: restricted | K5: work in progress | L5: transcribed | M5: Gunda Kinzl | N5: Maria Rebecca Zarb | Y5: Free Speech | AA5: Saudi Arabia 2022 – Speaker 20 – Shepherd
A6: SAU_2022_Speaker20_traditionalaccessories | C6: Saudi Arabia Fieldwork Campaign Gunda Kinzl 2022 | D6: {=_xlfn.TEXTJOIN(", ", TRUE(), _xlfn._xlws.FILTER(Speakers_in_Recordings!$B$2:$B$1502,Speakers_in_Recordings!$A$2:$A$1502=Rcrdngs[[#This Row],[Text]],"[no speaker selected in Speakers_in_Recordings]"))} -> SAU_2022_Speaker20, SAU_2022_Gunda | E6: {=_xlfn.TEXTJOIN(", ", TRUE(), _xlfn._xlws.FILTER(Sbcts_Rcrdngs[Subject],Sbcts_Rcrdngs[Recording]=Rcrdngs[[#This Row],[Text]],"[no subject selected in Subjects_in_Recordings]"))} -> Tribal Traditions | F6: 44635 | G6: 03:55 | H6: audio_transcription | I6: public | J6: restricted | K6: work in progress | L6: transcribed | M6: Gunda Kinzl | N6: Maria Rebecca Zarb | Y6: Free Speech | AA6: Saudi Arabia 2022 – Speaker 20 – Traditional Accessories
A7: SAU_2022_Speaker20_traditionalkitchen | C7: Saudi Arabia Fieldwork Campaign Gunda Kinzl 2022 | D7: {=_xlfn.TEXTJOIN(", ", TRUE(), _xlfn._xlws.FILTER(Speakers_in_Recordings!$B$2:$B$1502,Speakers_in_Recordings!$A$2:$A$1502=Rcrdngs[[#This Row],[Text]],"[no speaker selected in Speakers_in_Recordings]"))} -> SAU_2022_Speaker20, SAU_2022_Gunda, SAU_2022_Speaker9, SAU_2022_CulturalInformant | E7: {=_xlfn.TEXTJOIN(", ", TRUE(), _xlfn._xlws.FILTER(Sbcts_Rcrdngs[Subject],Sbcts_Rcrdngs[Recording]=Rcrdngs[[#This Row],[Text]],"[no subject selected in Subjects_in_Recordings]"))} -> Tribal Traditions | F7: 44635 | G7: 01:50 | H7: audio_transcription | I7: public | J7: restricted | K7: work in progress | L7: transcribed | M7: Gunda Kinzl | N7: Maria Rebecca Zarb | Y7: Free Speech | AA7: Saudi Arabia 2022 – Speaker 20 – Traditional Kitchen
A8: SAU_2022_Speaker20_moretraditionalthings | C8: Saudi Arabia Fieldwork Campaign Gunda Kinzl 2022 | D8: {=_xlfn.TEXTJOIN(", ", TRUE(), _xlfn._xlws.FILTER(Speakers_in_Recordings!$B$2:$B$1502,Speakers_in_Recordings!$A$2:$A$1502=Rcrdngs[[#This Row],[Text]],"[no speaker selected in Speakers_in_Recordings]"))} -> SAU_2022_Speaker20, SAU_2022_Gunda, SAU_2022_Speaker9, SAU_2022_CulturalInformant | E8: {=_xlfn.TEXTJOIN(", ", TRUE(), _xlfn._xlws.FILTER(Sbcts_Rcrdngs[Subject],Sbcts_Rcrdngs[Recording]=Rcrdngs[[#This Row],[Text]],"[no subject selected in Subjects_in_Recordings]"))} -> Tribal Traditions | F8: 44635 | G8: 03:30 | H8: audio_transcription | I8: public | J8: restricted | K8: work in progress | L8: transcribed | M8: Gunda Kinzl | N8: Maria Rebecca Zarb | Y8: Free Speech | AA8: Saudi Arabia 2022 – Speaker 20 – More Traditional Items
A9: SAU_2022_Speaker14_childhood_womenswork | C9: Saudi Arabia Fieldwork Campaign Gunda Kinzl 2022 | D9: {=_xlfn.TEXTJOIN(", ", TRUE(), _xlfn._xlws.FILTER(Speakers_in_Recordings!$B$2:$B$1502,Speakers_in_Recordings!$A$2:$A$1502=Rcrdngs[[#This Row],[Text]],"[no speaker selected in Speakers_in_Recordings]"))} -> SAU_2022_Speaker14, SAU_2022_Gunda | E9: {=_xlfn.TEXTJOIN(", ", TRUE(), _xlfn._xlws.FILTER(Sbcts_Rcrdngs[Subject],Sbcts_Rcrdngs[Recording]=Rcrdngs[[#This Row],[Text]],"[no subject selected in Subjects_in_Recordings]"))} -> Women's work, Childhood | F9: 44638 | G9: 06:46 | H9: audio_transcription | I9: restricted | J9: restricted | K9: work in progress | L9: transcribed | M9: Gunda Kinzl | N9: Maria Rebecca Zarb | U9: Khaybar | Y9: Free Speech | AA9: Saudi Arabia 2022 – Speaker 14 – Childhood; Women’s Work
A10: KUW_2022_Speaker8_neighbourhood | B10: KUW_2022_Speaker8_education | C10: Kuwait Fieldwork Campaign Gunda Kinzl 2022 | D10: {=_xlfn.TEXTJOIN(", ", TRUE(), _xlfn._xlws.FILTER(Speakers_in_Recordings!$B$2:$B$1502,Speakers_in_Recordings!$A$2:$A$1502=Rcrdngs[[#This Row],[Text]],"[no speaker selected in Speakers_in_Recordings]"))} -> KUW_2022_Speaker8, KUW_2022_Speaker6, KUW_2022_Gunda | E10: {=_xlfn.TEXTJOIN(", ", TRUE(), _xlfn._xlws.FILTER(Sbcts_Rcrdngs[Subject],Sbcts_Rcrdngs[Recording]=Rcrdngs[[#This Row],[Text]],"[no subject selected in Subjects_in_Recordings]"))} -> Houses | F10: 44701 | G10: 04:58 | H10: audio_transcription | I10: public | J10: restricted | K10: work in progress | L10: transcribed | M10: Gunda Kinzl | N10: Maria Rebecca Zarb | U10: Kuwait City | X10: I have to see which I want to use for my thesis from this speaker | Y10: Free Speech | AA10: Kuwait 2022 – Speaker 8 – Neighbourhood
A11: KUW_2022_Speaker8_education | B11: KUW_2022_Speaker8_family | C11: Kuwait Fieldwork Campaign Gunda Kinzl 2022 | D11: {=_xlfn.TEXTJOIN(", ", TRUE(), _xlfn._xlws.FILTER(Speakers_in_Recordings!$B$2:$B$1502,Speakers_in_Recordings!$A$2:$A$1502=Rcrdngs[[#This Row],[Text]],"[no speaker selected in Speakers_in_Recordings]"))} -> KUW_2022_Speaker8, KUW_2022_Gunda | E11: {=_xlfn.TEXTJOIN(", ", TRUE(), _xlfn._xlws.FILTER(Sbcts_Rcrdngs[Subject],Sbcts_Rcrdngs[Recording]=Rcrdngs[[#This Row],[Text]],"[no subject selected in Subjects_in_Recordings]"))} -> Education | F11: 44701 | G11: 01:03 | H11: audio_transcription | I11: public | J11: restricted | K11: work in progress | L11: transcribed | M11: Gunda Kinzl | N11: Maria Rebecca Zarb | U11: Kuwait City | Y11: Free Speech | AA11: Kuwait 2022 – Speaker 8 – Education
A12: KUW_2022_Speaker8_family | B12: KUW_2022_Speaker8_wedding | C12: Kuwait Fieldwork Campaign Gunda Kinzl 2022 | D12: {=_xlfn.TEXTJOIN(", ", TRUE(), _xlfn._xlws.FILTER(Speakers_in_Recordings!$B$2:$B$1502,Speakers_in_Recordings!$A$2:$A$1502=Rcrdngs[[#This Row],[Text]],"[no speaker selected in Speakers_in_Recordings]"))} -> KUW_2022_Speaker8, KUW_2022_Gunda | E12: {=_xlfn.TEXTJOIN(", ", TRUE(), _xlfn._xlws.FILTER(Sbcts_Rcrdngs[Subject],Sbcts_Rcrdngs[Recording]=Rcrdngs[[#This Row],[Text]],"[no subject selected in Subjects_in_Recordings]"))} -> Family | F12: 44701 | G12: 03:03 | H12: audio_transcription | I12: public | J12: restricted | K12: work in progress | L12: transcribed | M12: Gunda Kinzl | N12: Maria Rebecca Zarb | U12: Kuwait City | Y12: Free Speech | AA12: Kuwait 2022 – Speaker 8 – Family
A13: KUW_2022_Speaker8_wedding | B13: KUW_2022_Speaker8_lifedevelopments_cooking | C13: Kuwait Fieldwork Campaign Gunda Kinzl 2022 | D13: {=_xlfn.TEXTJOIN(", ", TRUE(), _xlfn._xlws.FILTER(Speakers_in_Recordings!$B$2:$B$1502,Speakers_in_Recordings!$A$2:$A$1502=Rcrdngs[[#This Row],[Text]],"[no speaker selected in Speakers_in_Recordings]"))} -> KUW_2022_Speaker8, KUW_2022_Gunda | E13: {=_xlfn.TEXTJOIN(", ", TRUE(), _xlfn._xlws.FILTER(Sbcts_Rcrdngs[Subject],Sbcts_Rcrdngs[Recording]=Rcrdngs[[#This Row],[Text]],"[no subject selected in Subjects_in_Recordings]"))} -> Marriage | F13: 44701 | G13: 09:52 | H13: audio_transcription | I13: restricted | J13: restricted | K13: work in progress | L13: transcribed | M13: Gunda Kinzl | N13: Maria Rebecca Zarb | U13: Kuwait City | Y13: Free Speech | AA13: Kuwait 2022 – Speaker 8 – Wedding
A14: KUW_2022_Speaker8_lifedevelopments_cooking | C14: Kuwait Fieldwork Campaign Gunda Kinzl 2022 | D14: {=_xlfn.TEXTJOIN(", ", TRUE(), _xlfn._xlws.FILTER(Speakers_in_Recordings!$B$2:$B$1502,Speakers_in_Recordings!$A$2:$A$1502=Rcrdngs[[#This Row],[Text]],"[no speaker selected in Speakers_in_Recordings]"))} -> KUW_2022_Speaker8, KUW_2022_Speaker6, KUW_2022_Gunda | E14: {=_xlfn.TEXTJOIN(", ", TRUE(), _xlfn._xlws.FILTER(Sbcts_Rcrdngs[Subject],Sbcts_Rcrdngs[Recording]=Rcrdngs[[#This Row],[Text]],"[no subject selected in Subjects_in_Recordings]"))} -> Food recipees, Daily life | F14: 44701 | G14: 06:54 | H14: audio_transcription | I14: public | J14: restricted | K14: work in progress | L14: transcribed | M14: Gunda Kinzl | N14: Maria Rebecca Zarb | U14: Kuwait City | Y14: Free Speech | AA14: Kuwait 2022 – Speaker 8 – Life Developments; Cooking
A15: KUW_2022_Speaker8_war_goodandbadexperiences_differenceswithinrashayda | C15: Kuwait Fieldwork Campaign Gunda Kinzl 2022 | D15: {=_xlfn.TEXTJOIN(", ", TRUE(), _xlfn._xlws.FILTER(Speakers_in_Recordings!$B$2:$B$1502,Speakers_in_Recordings!$A$2:$A$1502=Rcrdngs[[#This Row],[Text]],"[no speaker selected in Speakers_in_Recordings]"))} -> KUW_2022_Speaker8, KUW_2022_Gunda | E15: {=_xlfn.TEXTJOIN(", ", TRUE(), _xlfn._xlws.FILTER(Sbcts_Rcrdngs[Subject],Sbcts_Rcrdngs[Recording]=Rcrdngs[[#This Row],[Text]],"[no subject selected in Subjects_in_Recordings]"))} -> Childhood, Family, Migration and diaspora | F15: 44701 | G15: 08:50 | H15: audio_transcription | I15: restricted | J15: restricted | L15: transcribed | M15: Gunda Kinzl | N15: Maria Rebecca Zarb | U15: Kuwait City | Y15: Free Speech | AA15: Kuwait 2022 – Speaker 8 – War: Good/Bad Experiences; Differences within Rashayda
A16: KUW_2022_Speaker8_Elicitations_PictureStories | C16: Kuwait Fieldwork Campaign Gunda Kinzl 2022 | D16: {=_xlfn.TEXTJOIN(", ", TRUE(), _xlfn._xlws.FILTER(Speakers_in_Recordings!$B$2:$B$1502,Speakers_in_Recordings!$A$2:$A$1502=Rcrdngs[[#This Row],[Text]],"[no speaker selected in Speakers_in_Recordings]"))} -> KUW_2022_Speaker8, KUW_2022_Gunda | E16: {=_xlfn.TEXTJOIN(", ", TRUE(), _xlfn._xlws.FILTER(Sbcts_Rcrdngs[Subject],Sbcts_Rcrdngs[Recording]=Rcrdngs[[#This Row],[Text]],"[no subject selected in Subjects_in_Recordings]"))} -> Visual elicitation | F16: 44701 | G16: 05:15 | H16: audio_transcription | I16: public | J16: restricted | K16: work in progress | L16: transcribed | M16: Gunda Kinzl | N16: Maria Rebecca Zarb | U16: Kuwait City | Y16: Elicitation | AA16: Kuwait 2022 – Speaker 8 – Elicitation: Picture Stories
A17: KUW_2022_Speaker8_Elicitations_TopologicalRelations | C17: Kuwait Fieldwork Campaign Gunda Kinzl 2022 | D17: {=_xlfn.TEXTJOIN(", ", TRUE(), _xlfn._xlws.FILTER(Speakers_in_Recordings!$B$2:$B$1502,Speakers_in_Recordings!$A$2:$A$1502=Rcrdngs[[#This Row],[Text]],"[no speaker selected in Speakers_in_Recordings]"))} -> KUW_2022_Speaker8, KUW_2022_Gunda | E17: {=_xlfn.TEXTJOIN(", ", TRUE(), _xlfn._xlws.FILTER(Sbcts_Rcrdngs[Subject],Sbcts_Rcrdngs[Recording]=Rcrdngs[[#This Row],[Text]],"[no subject selected in Subjects_in_Recordings]"))} -> Visual elicitation | F17: 44701 | G17: 09:15 | H17: audio_transcription | I17: public | J17: restricted | K17: work in progress | L17: transcribed | M17: Gunda Kinzl | N17: Maria Rebecca Zarb | U17: Kuwait City | Y17: Elicitation | AA17: Kuwait 2022 – Speaker 8 – Elicitation: Topological Relations
A18: KUW_2022_Speaker8_Elicitations_PictureStories_2 | C18: Kuwait Fieldwork Campaign Gunda Kinzl 2022 | D18: {=_xlfn.TEXTJOIN(", ", TRUE(), _xlfn._xlws.FILTER(Speakers_in_Recordings!$B$2:$B$1502,Speakers_in_Recordings!$A$2:$A$1502=Rcrdngs[[#This Row],[Text]],"[no speaker selected in Speakers_in_Recordings]"))} -> KUW_2022_Speaker8, KUW_2022_Speaker6, KUW_2022_Gunda | E18: {=_xlfn.TEXTJOIN(", ", TRUE(), _xlfn._xlws.FILTER(Sbcts_Rcrdngs[Subject],Sbcts_Rcrdngs[Recording]=Rcrdngs[[#This Row],[Text]],"[no subject selected in Subjects_in_Recordings]"))} -> Visual elicitation | F18: 44701 | G18: 05:00 | H18: audio_transcription | I18: public | J18: restricted | K18: work in progress | L18: transcribed | M18: Gunda Kinzl | N18: Maria Rebecca Zarb | U18: Kuwait City | Y18: Elicitation | AA18: Kuwait 2022 – Speaker 8 – Elicitation: Picture Stories (Part 2)
A19: KUW_2022_Speaker8_coffeetraditions | C19: Kuwait Fieldwork Campaign Gunda Kinzl 2022 | D19: {=_xlfn.TEXTJOIN(", ", TRUE(), _xlfn._xlws.FILTER(Speakers_in_Recordings!$B$2:$B$1502,Speakers_in_Recordings!$A$2:$A$1502=Rcrdngs[[#This Row],[Text]],"[no speaker selected in Speakers_in_Recordings]"))} -> KUW_2022_Speaker8, KUW_2022_Speaker6, KUW_2022_Gunda | E19: {=_xlfn.TEXTJOIN(", ", TRUE(), _xlfn._xlws.FILTER(Sbcts_Rcrdngs[Subject],Sbcts_Rcrdngs[Recording]=Rcrdngs[[#This Row],[Text]],"[no subject selected in Subjects_in_Recordings]"))} -> Coffee | F19: 44701 | G19: 02:30 | H19: audio_transcription | I19: public | J19: restricted | K19: work in progress | L19: transcribed | M19: Gunda Kinzl | N19: Maria Rebecca Zarb | U19: Kuwait City | Y19: Free Speech | AA19: Kuwait 2022 – Speaker 8 – Coffee Traditions
A20: KUW_2022_Speaker8_cooking | C20: Kuwait Fieldwork Campaign Gunda Kinzl 2022 | D20: {=_xlfn.TEXTJOIN(", ", TRUE(), _xlfn._xlws.FILTER(Speakers_in_Recordings!$B$2:$B$1502,Speakers_in_Recordings!$A$2:$A$1502=Rcrdngs[[#This Row],[Text]],"[no speaker selected in Speakers_in_Recordings]"))} -> KUW_2022_Speaker8, KUW_2022_Speaker6, KUW_2022_Gunda | E20: {=_xlfn.TEXTJOIN(", ", TRUE(), _xlfn._xlws.FILTER(Sbcts_Rcrdngs[Subject],Sbcts_Rcrdngs[Recording]=Rcrdngs[[#This Row],[Text]],"[no subject selected in Subjects_in_Recordings]"))} -> Food recipees | F20: 44701 | G20: 00:30 | H20: audio_transcription | I20: public | J20: restricted | K20: work in progress | L20: transcribed | M20: Gunda Kinzl | N20: Maria Rebecca Zarb | U20: Kuwait City | Y20: Free Speech | AA20: Kuwait 2022 – Speaker 8 – Cooking
A21: KUW_2022_Speaker8_traditionalmarket_recipe | C21: Kuwait Fieldwork Campaign Gunda Kinzl 2022 | D21: {=_xlfn.TEXTJOIN(", ", TRUE(), _xlfn._xlws.FILTER(Speakers_in_Recordings!$B$2:$B$1502,Speakers_in_Recordings!$A$2:$A$1502=Rcrdngs[[#This Row],[Text]],"[no speaker selected in Speakers_in_Recordings]"))} -> KUW_2022_Speaker8, KUW_2022_Speaker6, KUW_2022_Gunda | E21: {=_xlfn.TEXTJOIN(", ", TRUE(), _xlfn._xlws.FILTER(Sbcts_Rcrdngs[Subject],Sbcts_Rcrdngs[Recording]=Rcrdngs[[#This Row],[Text]],"[no subject selected in Subjects_in_Recordings]"))} -> Food recipees, Markets and food prices | F21: 44701 | G21: 05:00 | H21: audio_transcription | I21: public | J21: restricted | K21: work in progress | L21: transcribed | M21: Gunda Kinzl | N21: Maria Rebecca Zarb | U21: Kuwait City | Y21: Free Speech | AA21: Kuwait 2022 – Speaker 8 – Traditional Market; Recipe
A22: SAU_2022_Speaker14_houses_education | B22: SAU_2022_Speaker14_education_2 | C22: Saudi Arabia Fieldwork Campaign Gunda Kinzl 2022 | D22: {=_xlfn.TEXTJOIN(", ", TRUE(), _xlfn._xlws.FILTER(Speakers_in_Recordings!$B$2:$B$1502,Speakers_in_Recordings!$A$2:$A$1502=Rcrdngs[[#This Row],[Text]],"[no speaker selected in Speakers_in_Recordings]"))} -> SAU_2022_Speaker14, SAU_2022_Gunda, SAU_2022_SpeakerUnknown | E22: {=_xlfn.TEXTJOIN(", ", TRUE(), _xlfn._xlws.FILTER(Sbcts_Rcrdngs[Subject],Sbcts_Rcrdngs[Recording]=Rcrdngs[[#This Row],[Text]],"[no subject selected in Subjects_in_Recordings]"))} -> Houses, Education | F22: 44638 | G22: 09:58 | H22: audio_transcription | I22: restricted | J22: restricted | K22: work in progress | L22: transcribed | M22: Gunda Kinzl | N22: Maria Rebecca Zarb | U22: Khaybar | X22: This is the first recording of this session | Y22: Free Speech | AA22: Saudi Arabia 2022 – Speaker 14 – Houses; Education
A23: SAU_2022_Speaker14_education_2 | C23: Saudi Arabia Fieldwork Campaign Gunda Kinzl 2022 | D23: {=_xlfn.TEXTJOIN(", ", TRUE(), _xlfn._xlws.FILTER(Speakers_in_Recordings!$B$2:$B$1502,Speakers_in_Recordings!$A$2:$A$1502=Rcrdngs[[#This Row],[Text]],"[no speaker selected in Speakers_in_Recordings]"))} -> SAU_2022_Speaker14, SAU_2022_SpeakerUnknown, SAU_2022_Gunda | E23: {=_xlfn.TEXTJOIN(", ", TRUE(), _xlfn._xlws.FILTER(Sbcts_Rcrdngs[Subject],Sbcts_Rcrdngs[Recording]=Rcrdngs[[#This Row],[Text]],"[no subject selected in Subjects_in_Recordings]"))} -> Education | F23: 44638 | G23: 04:38 | H23: audio_transcription | I23: restricted | J23: restricted | K23: work in progress | L23: transcribed | M23: Gunda Kinzl | N23: Maria Rebecca Zarb | U23: Khaybar | X23: This is continuing with SAU_2022_Speaker14_houses_education | Y23: Free Speech | AA23: Saudi Arabia 2022 – Speaker 14 – Education (Part 2)
A24: SAU_2022_Speaker14_childhood | C24: Saudi Arabia Fieldwork Campaign Gunda Kinzl 2022 | D24: {=_xlfn.TEXTJOIN(", ", TRUE(), _xlfn._xlws.FILTER(Speakers_in_Recordings!$B$2:$B$1502,Speakers_in_Recordings!$A$2:$A$1502=Rcrdngs[[#This Row],[Text]],"[no speaker selected in Speakers_in_Recordings]"))} -> SAU_2022_Speaker14, SAU_2022_Gunda | E24: {=_xlfn.TEXTJOIN(", ", TRUE(), _xlfn._xlws.FILTER(Sbcts_Rcrdngs[Subject],Sbcts_Rcrdngs[Recording]=Rcrdngs[[#This Row],[Text]],"[no subject selected in Subjects_in_Recordings]"))} -> Childhood | F24: 44638 | G24: 04:00 | H24: audio_transcription | I24: restricted | J24: restricted | K24: work in progress | L24: transcribed | M24: Gunda Kinzl | N24: Maria Rebecca Zarb | U24: Khaybar | Y24: Free Speech | AA24: Saudi Arabia 2022 – Speaker 14 – Childhood
A25: SAU_2022_Speaker14_weddings_2 | C25: Saudi Arabia Fieldwork Campaign Gunda Kinzl 2022 | D25: {=_xlfn.TEXTJOIN(", ", TRUE(), _xlfn._xlws.FILTER(Speakers_in_Recordings!$B$2:$B$1502,Speakers_in_Recordings!$A$2:$A$1502=Rcrdngs[[#This Row],[Text]],"[no speaker selected in Speakers_in_Recordings]"))} -> SAU_2022_Speaker14, SAU_2022_SpeakerUnknown, SAU_2022_Gunda | E25: {=_xlfn.TEXTJOIN(", ", TRUE(), _xlfn._xlws.FILTER(Sbcts_Rcrdngs[Subject],Sbcts_Rcrdngs[Recording]=Rcrdngs[[#This Row],[Text]],"[no subject selected in Subjects_in_Recordings]"))} -> Marriage | F25: 44638 | G25: 0:49 | H25: audio_transcription | I25: restricted | J25: restricted | K25: work in progress | L25: transcribed | M25: Gunda Kinzl | N25: Maria Rebecca Zarb | U25: Khaybar | Y25: Free Speech | AA25: Saudi Arabia 2022 – Speaker 14 – Weddings (Part 2)
A26: SAU_2022_Speaker14_weddings_1 | B26: SAU_2022_Speaker14_weddings_2 | C26: Saudi Arabia Fieldwork Campaign Gunda Kinzl 2022 | D26: {=_xlfn.TEXTJOIN(", ", TRUE(), _xlfn._xlws.FILTER(Speakers_in_Recordings!$B$2:$B$1502,Speakers_in_Recordings!$A$2:$A$1502=Rcrdngs[[#This Row],[Text]],"[no speaker selected in Speakers_in_Recordings]"))} -> SAU_2022_Speaker14, SAU_2022_SpeakerUnknown, SAU_2022_Gunda | E26: {=_xlfn.TEXTJOIN(", ", TRUE(), _xlfn._xlws.FILTER(Sbcts_Rcrdngs[Subject],Sbcts_Rcrdngs[Recording]=Rcrdngs[[#This Row],[Text]],"[no subject selected in Subjects_in_Recordings]"))} -> Marriage | F26: 44638 | G26: 05:30 | H26: audio_transcription | I26: restricted | J26: restricted | K26: work in progress | L26: transcribed | M26: Gunda Kinzl | N26: Maria Rebecca Zarb | U26: Khaybar | X26: Actually is a continuation of SAU_2022_Speaker14_education_girls_3_driving, but it is such a change in topic that it does not need to follow it. | Y26: Free Speech | AA26: Saudi Arabia 2022 – Speaker 14 – Weddings (Part 1)
A27: KUW_2022_Speaker12_childhood_1 | B27: KUW_2022_Speaker12_childhood_2 | C27: Kuwait Fieldwork Campaign Gunda Kinzl 2022 | D27: {=_xlfn.TEXTJOIN(", ", TRUE(), _xlfn._xlws.FILTER(Speakers_in_Recordings!$B$2:$B$1502,Speakers_in_Recordings!$A$2:$A$1502=Rcrdngs[[#This Row],[Text]],"[no speaker selected in Speakers_in_Recordings]"))} -> KUW_2022_Speaker12, KUW_2022_Speaker16, KUW_2022_Gunda | E27: {=_xlfn.TEXTJOIN(", ", TRUE(), _xlfn._xlws.FILTER(Sbcts_Rcrdngs[Subject],Sbcts_Rcrdngs[Recording]=Rcrdngs[[#This Row],[Text]],"[no subject selected in Subjects_in_Recordings]"))} -> Childhood | F27: 44702 | G27: 01:13 | H27: audio_transcription | I27: public | J27: restricted | K27: work in progress | L27: transcribed | M27: Gunda Kinzl | N27: Maria Rebecca Zarb | U27: Kuwait City | Y27: Free Speech | AA27: Kuwait 2022 – Speaker 12 – Childhood (Part 1)
A28: KUW_2022_Speaker12_childhood_2 | B28: KUW_2022_Speaker12_childhood_3 | C28: Kuwait Fieldwork Campaign Gunda Kinzl 2022 | D28: {=_xlfn.TEXTJOIN(", ", TRUE(), _xlfn._xlws.FILTER(Speakers_in_Recordings!$B$2:$B$1502,Speakers_in_Recordings!$A$2:$A$1502=Rcrdngs[[#This Row],[Text]],"[no speaker selected in Speakers_in_Recordings]"))} -> KUW_2022_Speaker12, KUW_2022_Speaker16, KUW_2022_Gunda | E28: {=_xlfn.TEXTJOIN(", ", TRUE(), _xlfn._xlws.FILTER(Sbcts_Rcrdngs[Subject],Sbcts_Rcrdngs[Recording]=Rcrdngs[[#This Row],[Text]],"[no subject selected in Subjects_in_Recordings]"))} -> Childhood | F28: 44702 | G28: 01:13 | H28: audio_transcription | I28: public | J28: restricted | K28: work in progress | L28: transcribed | M28: Gunda Kinzl | N28: Maria Rebecca Zarb | U28: Kuwait City | Y28: Free Speech | AA28: Kuwait 2022 – Speaker 12 – Childhood (Part 2)
A29: KUW_2022_Speaker12_childhood_3 | C29: Kuwait Fieldwork Campaign Gunda Kinzl 2022 | D29: {=_xlfn.TEXTJOIN(", ", TRUE(), _xlfn._xlws.FILTER(Speakers_in_Recordings!$B$2:$B$1502,Speakers_in_Recordings!$A$2:$A$1502=Rcrdngs[[#This Row],[Text]],"[no speaker selected in Speakers_in_Recordings]"))} -> KUW_2022_Speaker12, KUW_2022_Speaker16, KUW_2022_Gunda | E29: {=_xlfn.TEXTJOIN(", ", TRUE(), _xlfn._xlws.FILTER(Sbcts_Rcrdngs[Subject],Sbcts_Rcrdngs[Recording]=Rcrdngs[[#This Row],[Text]],"[no subject selected in Subjects_in_Recordings]"))} -> Childhood | F29: 44702 | G29: 0:49 | H29: audio_transcription | I29: public | J29: restricted | K29: work in progress | L29: transcribed | M29: Gunda Kinzl | N29: Maria Rebecca Zarb | U29: Kuwait City | Y29: Free Speech | AA29: Kuwait 2022 – Speaker 12 – Childhood (Part 3)
A30: KUW_2022_Speaker12_childhood_4 | C30: Kuwait Fieldwork Campaign Gunda Kinzl 2022 | D30: {=_xlfn.TEXTJOIN(", ", TRUE(), _xlfn._xlws.FILTER(Speakers_in_Recordings!$B$2:$B$1502,Speakers_in_Recordings!$A$2:$A$1502=Rcrdngs[[#This Row],[Text]],"[no speaker selected in Speakers_in_Recordings]"))} -> KUW_2022_Speaker12, KUW_2022_Speaker16, KUW_2022_Gunda | E30: {=_xlfn.TEXTJOIN(", ", TRUE(), _xlfn._xlws.FILTER(Sbcts_Rcrdngs[Subject],Sbcts_Rcrdngs[Recording]=Rcrdngs[[#This Row],[Text]],"[no subject selected in Subjects_in_Recordings]"))} -> Childhood | F30: 44702 | G30: 02:20 | H30: audio_transcription | I30: public | J30: restricted | K30: work in progress | L30: transcribed | M30: Gunda Kinzl | N30: Maria Rebecca Zarb | U30: Kuwait City | Y30: Free Speech | AA30: Kuwait 2022 – Speaker 12 – Childhood (Part 4)
A31: KUW_2022_Speaker12_childhood_5 | C31: Kuwait Fieldwork Campaign Gunda Kinzl 2022 | D31: {=_xlfn.TEXTJOIN(", ", TRUE(), _xlfn._xlws.FILTER(Speakers_in_Recordings!$B$2:$B$1502,Speakers_in_Recordings!$A$2:$A$1502=Rcrdngs[[#This Row],[Text]],"[no speaker selected in Speakers_in_Recordings]"))} -> KUW_2022_Speaker12, KUW_2022_Speaker16, KUW_2022_Speaker17 | E31: {=_xlfn.TEXTJOIN(", ", TRUE(), _xlfn._xlws.FILTER(Sbcts_Rcrdngs[Subject],Sbcts_Rcrdngs[Recording]=Rcrdngs[[#This Row],[Text]],"[no subject selected in Subjects_in_Recordings]"))} -> Childhood | F31: 44702 | G31: 02:26 | H31: audio_transcription | I31: restricted | J31: restricted | L31: transcribed | M31: Gunda Kinzl | N31: Maria Rebecca Zarb | U31: Kuwait City | Y31: Free Speech | AA31: Kuwait 2022 – Speaker 12 – Childhood (Part 5)
A32: SAU_2022_Speaker14_education_girls_1 | B32: SAU_2022_Speaker14_education_girls_2 | C32: Saudi Arabia Fieldwork Campaign Gunda Kinzl 2022 | D32: {=_xlfn.TEXTJOIN(", ", TRUE(), _xlfn._xlws.FILTER(Speakers_in_Recordings!$B$2:$B$1502,Speakers_in_Recordings!$A$2:$A$1502=Rcrdngs[[#This Row],[Text]],"[no speaker selected in Speakers_in_Recordings]"))} -> SAU_2022_Speaker14, SAU_2022_Gunda | E32: {=_xlfn.TEXTJOIN(", ", TRUE(), _xlfn._xlws.FILTER(Sbcts_Rcrdngs[Subject],Sbcts_Rcrdngs[Recording]=Rcrdngs[[#This Row],[Text]],"[no subject selected in Subjects_in_Recordings]"))} -> Education, Childhood | F32: 44638 | G32: 06:12 | H32: audio_transcription | I32: restricted | J32: restricted | K32: work in progress | L32: transcribed | M32: Gunda Kinzl | N32: Maria Rebecca Zarb | U32: Khaybar | Y32: Free Speech | AA32: Saudi Arabia 2022 – Speaker 14 – Education (Girls) (Part 1)
A33: SAU_2022_Speaker14_education_girls_2 | B33: SAU_2022_Speaker14_education_girls_3_driving | C33: Saudi Arabia Fieldwork Campaign Gunda Kinzl 2022 | D33: {=_xlfn.TEXTJOIN(", ", TRUE(), _xlfn._xlws.FILTER(Speakers_in_Recordings!$B$2:$B$1502,Speakers_in_Recordings!$A$2:$A$1502=Rcrdngs[[#This Row],[Text]],"[no speaker selected in Speakers_in_Recordings]"))} -> SAU_2022_Speaker14, SAU_2022_Gunda | E33: {=_xlfn.TEXTJOIN(", ", TRUE(), _xlfn._xlws.FILTER(Sbcts_Rcrdngs[Subject],Sbcts_Rcrdngs[Recording]=Rcrdngs[[#This Row],[Text]],"[no subject selected in Subjects_in_Recordings]"))} -> Education, Childhood | F33: 44638 | G33: 08:25 | H33: audio_transcription | I33: restricted | J33: restricted | K33: work in progress | L33: transcribed | M33: Gunda Kinzl | N33: Maria Rebecca Zarb | U33: Khaybar | Y33: Free Speech | AA33: Saudi Arabia 2022 – Speaker 14 – Education (Girls) (Part 2)
A34: SAU_2022_Speaker14_education_girls_3_driving | C34: Saudi Arabia Fieldwork Campaign Gunda Kinzl 2022 | D34: {=_xlfn.TEXTJOIN(", ", TRUE(), _xlfn._xlws.FILTER(Speakers_in_Recordings!$B$2:$B$1502,Speakers_in_Recordings!$A$2:$A$1502=Rcrdngs[[#This Row],[Text]],"[no speaker selected in Speakers_in_Recordings]"))} -> SAU_2022_Speaker14, SAU_2022_Gunda | E34: {=_xlfn.TEXTJOIN(", ", TRUE(), _xlfn._xlws.FILTER(Sbcts_Rcrdngs[Subject],Sbcts_Rcrdngs[Recording]=Rcrdngs[[#This Row],[Text]],"[no subject selected in Subjects_in_Recordings]"))} -> Education, Childhood, Driving | F34: 44638 | G34: 05:32 | H34: audio_transcription | I34: restricted | J34: restricted | K34: work in progress | L34: transcribed | M34: Gunda Kinzl | N34: Maria Rebecca Zarb | U34: Khaybar | Y34: Free Speech | AA34: Saudi Arabia 2022 – Speaker 14 – Education (Girls) (Part 3); Driving
A35: SAU_2022_Speaker19_market | C35: Saudi Arabia Fieldwork Campaign Gunda Kinzl 2022 | D35: {=_xlfn.TEXTJOIN(", ", TRUE(), _xlfn._xlws.FILTER(Speakers_in_Recordings!$B$2:$B$1502,Speakers_in_Recordings!$A$2:$A$1502=Rcrdngs[[#This Row],[Text]],"[no speaker selected in Speakers_in_Recordings]"))} -> SAU_2022_Speaker19, SAU_2022_UnknownMarketSeller, SAU_2022_Gunda | E35: {=_xlfn.TEXTJOIN(", ", TRUE(), _xlfn._xlws.FILTER(Sbcts_Rcrdngs[Subject],Sbcts_Rcrdngs[Recording]=Rcrdngs[[#This Row],[Text]],"[no subject selected in Subjects_in_Recordings]"))} -> Markets and food prices | F35: 44638 | G35: 01:47 | H35: audio_transcription | I35: public | J35: restricted | K35: work in progress | L35: transcribed | M35: Gunda Kinzl | N35: Maria Rebecca Zarb | U35: Khaybar | Y35: Free Speech | AA35: Saudi Arabia 2022 – Speaker 19 – Market
A36: SAU_2022_Speaker47_games_pets | C36: Saudi Arabia Fieldwork Campaign Gunda Kinzl 2022 | D36: {=_xlfn.TEXTJOIN(", ", TRUE(), _xlfn._xlws.FILTER(Speakers_in_Recordings!$B$2:$B$1502,Speakers_in_Recordings!$A$2:$A$1502=Rcrdngs[[#This Row],[Text]],"[no speaker selected in Speakers_in_Recordings]"))} -> SAU_2022_Gunda, SAU_2022_Speaker9, SAU_2022_Speaker47, SAU_2022_DaughterofSheikh2, SAU_2022_Speaker34 | E36: {=_xlfn.TEXTJOIN(", ", TRUE(), _xlfn._xlws.FILTER(Sbcts_Rcrdngs[Subject],Sbcts_Rcrdngs[Recording]=Rcrdngs[[#This Row],[Text]],"[no subject selected in Subjects_in_Recordings]"))} -> Childhood, Pets | F36: 44633 | G36: 06:45 | H36: audio_transcription | I36: restricted | J36: restricted | K36: work in progress | L36: transcribed | M36: Gunda Kinzl | N36: Maria Rebecca Zarb | U36: Ha'il | Y36: Free Speech | AA36: Saudi Arabia 2022 – Speaker 47 – Games and Pets
A37: SAU_2022_Speaker37_childhood | B37: SAU_2022_Speaker37_childhood2_marriage | C37: Saudi Arabia Fieldwork Campaign Gunda Kinzl 2022 | D37: {=_xlfn.TEXTJOIN(", ", TRUE(), _xlfn._xlws.FILTER(Speakers_in_Recordings!$B$2:$B$1502,Speakers_in_Recordings!$A$2:$A$1502=Rcrdngs[[#This Row],[Text]],"[no speaker selected in Speakers_in_Recordings]"))} -> SAU_2022_Speaker37, SAU_2022_Speaker23, SAU_2022_Gunda | E37: {=_xlfn.TEXTJOIN(", ", TRUE(), _xlfn._xlws.FILTER(Sbcts_Rcrdngs[Subject],Sbcts_Rcrdngs[Recording]=Rcrdngs[[#This Row],[Text]],"[no subject selected in Subjects_in_Recordings]"))} -> Childhood | F37: 44637 | G37: 07:30 | H37: audio_transcription | I37: restricted | J37: restricted | K37: work in progress | L37: transcribed | M37: Gunda Kinzl | N37: Maria Rebecca Zarb | U37: Khaybar | Y37: Free Speech | AA37: Saudi Arabia 2022 – Speaker 37 – Childhood
A38: SAU_2022_Speaker37_childhood2_marriage | C38: Saudi Arabia Fieldwork Campaign Gunda Kinzl 2022 | D38: {=_xlfn.TEXTJOIN(", ", TRUE(), _xlfn._xlws.FILTER(Speakers_in_Recordings!$B$2:$B$1502,Speakers_in_Recordings!$A$2:$A$1502=Rcrdngs[[#This Row],[Text]],"[no speaker selected in Speakers_in_Recordings]"))} -> SAU_2022_Speaker37, SAU_2022_Speaker23, SAU_2022_Gunda | E38: {=_xlfn.TEXTJOIN(", ", TRUE(), _xlfn._xlws.FILTER(Sbcts_Rcrdngs[Subject],Sbcts_Rcrdngs[Recording]=Rcrdngs[[#This Row],[Text]],"[no subject selected in Subjects_in_Recordings]"))} -> Marriage | F38: 44637 | G38: 07:30 | H38: audio_transcription | I38: restricted | J38: restricted | K38: work in progress | L38: transcribed | M38: Gunda Kinzl | N38: Maria Rebecca Zarb | U38: Khaybar | Y38: Free Speech | AA38: Saudi Arabia 2022 – Speaker 37 – Childhood (2); Marriage
A39: SAU_2022_Speaker37_camel | C39: Saudi Arabia Fieldwork Campaign Gunda Kinzl 2022 | D39: {=_xlfn.TEXTJOIN(", ", TRUE(), _xlfn._xlws.FILTER(Speakers_in_Recordings!$B$2:$B$1502,Speakers_in_Recordings!$A$2:$A$1502=Rcrdngs[[#This Row],[Text]],"[no speaker selected in Speakers_in_Recordings]"))} -> SAU_2022_Speaker37, SAU_2022_Speaker23, SAU_2022_Gunda | E39: {=_xlfn.TEXTJOIN(", ", TRUE(), _xlfn._xlws.FILTER(Sbcts_Rcrdngs[Subject],Sbcts_Rcrdngs[Recording]=Rcrdngs[[#This Row],[Text]],"[no subject selected in Subjects_in_Recordings]"))} -> Herding | F39: 44637 | G39: 02:57 | H39: audio_transcription | I39: restricted | J39: restricted | K39: work in progress | L39: transcribed | M39: Gunda Kinzl | N39: Maria Rebecca Zarb | U39: Khaybar | Y39: Free Speech | AA39: Saudi Arabia 2022 – Speaker 37 – Camel
A40: SAU_2022_Speaker37_food_3eyb_haram | B40: SAU_2022_3eyb_haram_2 | C40: Saudi Arabia Fieldwork Campaign Gunda Kinzl 2022 | D40: {=_xlfn.TEXTJOIN(", ", TRUE(), _xlfn._xlws.FILTER(Speakers_in_Recordings!$B$2:$B$1502,Speakers_in_Recordings!$A$2:$A$1502=Rcrdngs[[#This Row],[Text]],"[no speaker selected in Speakers_in_Recordings]"))} -> SAU_2022_Speaker37, SAU_2022_Speaker23, SAU_2022_Gunda | E40: {=_xlfn.TEXTJOIN(", ", TRUE(), _xlfn._xlws.FILTER(Sbcts_Rcrdngs[Subject],Sbcts_Rcrdngs[Recording]=Rcrdngs[[#This Row],[Text]],"[no subject selected in Subjects_in_Recordings]"))} -> Concept of 3eyb and Haram | F40: 44637 | G40: 02:47 | H40: audio_transcription | I40: restricted | J40: restricted | K40: work in progress | L40: transcribed | M40: Gunda Kinzl | N40: Maria Rebecca Zarb | U40: Khaybar | Y40: Free Speech | AA40: Saudi Arabia 2022 – Speaker 37 – Food; Ayb and Haram
...

Sheet Team
A1: forename | B1: surname | C1: affiliation.Element:Text | D1: http://www.w3.org/XML/1998/namespace.Attribute:id | E1: Attribute:role | F1: note | G1: persName
A2: Stephan | B2: Procházka | C2: University of Vienna, Department of Near Eastern Studies | D2: SP | E2: Principal investigator | G2: Stephan Procházka
A3: Maria Rebecca | B3: Zarb | C3: University of Vienna, Department of Near Eastern Studies | D3: RZ | E3: Prae-doc researcher | F3: deals with the dialect of the Rašāyda bedouins namely in Saudi Arabia and Kuwait. WP1 | G3: Maria Rebecca Zarb
A4: Johanna | B4: Doppelbauer | C4: University of Vienna, Department of Near Eastern Studies | D4: JD | E4: Pre-MA researcher | F4: collection of data for the database. This includes finding information regarding Bedouin dialects from already published sources and, once the database is operational, feeding it with the information accumulated on the subject, along with the data that will be collected by the other researchers in the course of the project. WP4 | G4: Johanna Doppelbauer
A5: Stanley | B5: Kochem | C5: University of Vienna, Department of Near Eastern Studies | D5: SK | E5: Pre-MA researcher | F5: collection of data for the database. This includes finding information regarding Bedouin dialects from already published sources and, once the database is operational, feeding it with the information accumulated on the subject, along with the data that will be collected by the other researchers in the course of the project. WP4 | G5: Stanley Kochem
A6: Ana | B6: Iriarte Díez | C6: University of Vienna, Department of Near Eastern Studies | D6: AID | E6: Post-doc researcher | F6: works on language and dialect contact and historical linguistics and language change WP5, WP6 | G6: Ana Iriarte Díez
A7: Gisela | B7: Kitzler | C7: University of Vienna, Department of Near Eastern Studies | D7: GiK | E7: Post-doc researcher | F7: works on the perception of bedouin varieties in Egypt with a focus on Sinai, as well as accommodation between bedouin and non-bedouin varieties in tourist areas in South Sinai. In Addition, she is responsible for the coordination of the project WP2 | G7: Gisela Kitzler
A8: Antonella | B8: Torzullo | C8: University of Vienna, Department of Near Eastern Studies | D8: AT | E8: Prae-doc researcher | F8: works on the Arabic dialect of the Bani Saxar tribe in Jordan WP1 | G8: Antonella Torzullo
A9: Terlan | B9: Djavadova | C9: University of Vienna, Department of Near Eastern Studies | D9: TD | E9: Prae-doc researcher | F9: deals with the Bedouin dialects of the ZAer and Chouia in Morocco and their influence on the Moroccan Koina WP1 | G9: Terlan Djavadova
A10: Claudia | B10: Laaber | C10: University of Vienna, Department of Near Eastern Studies | D10: CL | E10: Prae-doc researcher | F10: works on language attitudes towards Bedouin Arabic WP2 | G10: Claudia Laaber
A11: Gunda | B11: Kinzl | C11: University of Vienna, Department of Near Eastern Studies | D11: GuK | E11: Prae-doc researcher | F11: works on a grammatical description of the Rashayda Bedouins’ dialect in Saudi Arabia and Sudan WP1 | G11: Gunda Kinzl
A12: Veronika | B12: Engler | C12: Austrian Academy of Sciences, ACDH-CH | D12: VE | E12: Technical Staff | F12: collection of data for the database. This includes finding information regarding Bedouin dialects from already published sources and, once the database is operational, feeding it with the information accumulated on the subject, along with the data that will be collected by the other researchers in the course of the project. | G12: Veronika Engler
A13: Philipp | B13: Hessabi | C13: University of Vienna, Department of Near Eastern Studies | D13: PH | E13: Pre-MA researcher | F13: collection of data for the database. This includes finding information regarding Bedouin dialects from already published sources and, once the database is operational, feeding it with the information accumulated on the subject, along with the data that will be collected by the other researchers in the course of the project. WP4 | G13: Philipp Hessabi
A14: Kadir | B14: Mustafaoglu | C14: University of Vienna, Department of Near Eastern Studies | D14: AKM | E14: Pre-MA researcher | F14: collection of data for the database. This includes finding information regarding Bedouin dialects from already published sources and, once the database is operational, feeding it with the information accumulated on the subject, along with the data that will be collected by the other researchers in the course of the project. WP4 | G14: Kadir Mustafaoglu
A15: Charly | B15: Mörth | C15: Austrian Academy of Sciences, ACDH-CH | D15: CM | E15: National Project Partner | G15: Charly Mörth
A16: Angelika | B16: Hechtl | C16: Austrian Academy of Sciences, ACDH-CH | D16: AH | E16: Technical Staff | G16: Angelika Hechtl
A17: Kinga | B17: Sramó | C17: Austrian Academy of Sciences, ACDH-CH | D17: KS | E17: Technical Staff | F17: works on transforming the linguistic data from the database into a visual representation (map) | G17: Kinga Sramó
A18: Daniel | B18: Schopper | C18: Austrian Academy of Sciences, ACDH-CH | D18: DS | E18: Senior Technical Consultant | F18: senior advisor on TEI modelling, head of working group Data@ACDH-CH; MS Teams and sharepoint admin | G18: Daniel Schopper
A19: Maura Zsófia | B19: Abraham | C19: Austrian Academy of Sciences, ACDH-CH | D19: MA | E19: Technical Consultant | F19: works on the SHAWI and TUNOCENT projects. We try to keep technical developments in all three projects in sync with each other, so she will participate / advise on relevant points. | G19: Maura Zsófia Abraham
A20: Omar | B20: Siam | C20: Austrian Academy of Sciences, ACDH-CH | D20: OS | E20: Senior Technical Consultant | F20: senior advisor, system administrator at ACDH-CH, technical supervisor for the VICAV infrastructure | G20: Omar Siam
H21: DO NOT EDIT
H22: The content of this sheet is fetched from 010_manannot/wibarab_dmp.xml

Sheet Status
A1: Status | B1: Description
A2: recorded | B2: initial state, nothing has been done with this recording
A3: anonymized | B3: the recording has been checked for sensitive data and been anonymized (beeped) - THIS IS NECESSARY BEFORE BEING ABLE TO PROCESS THE DATA
A4: transcribed | B4: the text has been transcribed in ELAN
A5: glossed | B5: the text has been glossed (optional)
A6: translated | B6: the text has been translated (optional)
A7: ready for processing | B7: the text is ready for being transformed to TEI
A8: ready for publication | B8: the text can be published

Sheet Speakers
A1: Speaker | B1: CONSENT | C1: Gender | D1: Year of Birth | E1: Age Group | F1: Age Group Comment | G1: Languages | H1: Place of Origin | I1: Note | J1: Recordings | K1: Tribe | L1: Mother origin | M1: Cattle-related business | N1: Education | O1: Speaker Label
A2: SAU_2022_Speaker10 | B2: YES | C2: F | D2: 1990s | E2: 30s | H2: Saudi Arabia | I2: She has one recording, the marriage audio. I have split this into _marriage_1 and marriage_2 | J2: {=_xlfn.TEXTJOIN(", ",TRUE(),_xlfn._xlws.FILTER(Speakers_in_Recordings!$A$2:$A$1502,Speakers_in_Recordings!$B$2:$B$1502=_xlfn.SINGLE(Spkrs[Speaker]),"N/A"))} -> SAU_2022_Speaker10_marriage_1, SAU_2022_Speaker10_marriage_2 | K2: Rašāyda
A3: SAU_2022_Speaker20 | B3: YES | C3: M | E3: 70s | H3: Saudi Arabia | J3: {=_xlfn.TEXTJOIN(", ",TRUE(),_xlfn._xlws.FILTER(Speakers_in_Recordings!$A$2:$A$1502,Speakers_in_Recordings!$B$2:$B$1502=_xlfn.SINGLE(Spkrs[Speaker]),"N/A"))} -> SAU_2022_Speaker20_traditionaltools, SAU_2022_Speaker20_shepherd, SAU_2022_Speaker20_traditionalaccessories, SAU_2022_Speaker20_traditionalkitchen, SAU_2022_Speaker20_moretraditionalthings | K3: Rašāyda
A4: SAU_2022_Speaker19 | B4: YES | C4: M | E4: 50s | H4: Saudi Arabia | I4: No metadata but we have consent | J4: {=_xlfn.TEXTJOIN(", ",TRUE(),_xlfn._xlws.FILTER(Speakers_in_Recordings!$A$2:$A$1502,Speakers_in_Recordings!$B$2:$B$1502=_xlfn.SINGLE(Spkrs[Speaker]),"N/A"))} -> SAU_2022_Speaker19_market | K4: Rašāyda
A5: SAU_2022_CulturalInformant | B5: NO | C5: M | E5: 50s | H5: Saudi Arabia | I5: no information or consent on this guy | J5: {=_xlfn.TEXTJOIN(", ",TRUE(),_xlfn._xlws.FILTER(Speakers_in_Recordings!$A$2:$A$1502,Speakers_in_Recordings!$B$2:$B$1502=_xlfn.SINGLE(Spkrs[Speaker]),"N/A"))} -> SAU_2022_Speaker20_traditionaltools, SAU_2022_Speaker20_traditionalkitchen, SAU_2022_Speaker20_moretraditionalthings
A6: SAU_2022_Speaker9 | B6: YES | C6: M | D6: 1960 | E6: 60s | H6: Saudi Arabia | I6: abs chief, head of rabtat abs, accompanied gunda on all the trips, appears in almost all audios expect for the ones conducted with women | J6: {=_xlfn.TEXTJOIN(", ",TRUE(),_xlfn._xlws.FILTER(Speakers_in_Recordings!$A$2:$A$1502,Speakers_in_Recordings!$B$2:$B$1502=_xlfn.SINGLE(Spkrs[Speaker]),"N/A"))} -> SAU_2022_Speaker20_traditionaltools, SAU_2022_Speaker20_traditionalkitchen, SAU_2022_Speaker20_moretraditionalthings, SAU_2022_Speaker47_games_pets, SAU_2022_Speaker9_qasida, SAU_2022_Speaker9_family_school, SAU_2022_Speaker25_poetry_recital, SAU_2022_Speaker43_tribe_abs, SAU_2022_Speaker43_conversation, SAU_2022_Speaker24_qasida_reading, SAU_2022_Speaker9_camels_1, SAU_2022_Speaker9_camels_2, SAU_2022_Speaker9_camels_3, SAU_2022_Speaker9_camels_4, SAU_2022_Speaker9_camels_5, SAU_2022_Speaker9_camels_6, SAU_2022_Speaker44_falcons_1, SAU_2022_Speaker44_falcons_2, SAU_2022_Speaker9_poetry_1, SAU_2022_Speaker21_interviews, SAU_2022_Speaker50_interviews, SAU_2022_Speaker51_interviews, SAU_2022_Speaker52_interviews, SAU_2022_Speaker28_conversation_Oldman_1, SAU_2022_Speaker28_conversation_Oldman_2, SAU_2022_Speaker28_conversation_Oldman_4, SAU_2022_Speaker28_conversation_Oldman_5 | K6: Rašāyda | N6: university, he is a doctor
A7: SAU_2022_UnknownMarketSeller | B7: NO | C7: M | E7: 60s | H7: Saudi Arabia | I7: no metadata, no consent | J7: {=_xlfn.TEXTJOIN(", ",TRUE(),_xlfn._xlws.FILTER(Speakers_in_Recordings!$A$2:$A$1502,Speakers_in_Recordings!$B$2:$B$1502=_xlfn.SINGLE(Spkrs[Speaker]),"N/A"))} -> SAU_2022_Speaker19_market
A8: SAU_2022_Speaker14 | B8: YES | C8: F | D8: 1980 | E8: 40s | H8: Saudi Arabia | I8: teacher living in Khaybar, very bubbly woman, mother, very interested in culture and the arts | J8: {=_xlfn.TEXTJOIN(", ",TRUE(),_xlfn._xlws.FILTER(Speakers_in_Recordings!$A$2:$A$1502,Speakers_in_Recordings!$B$2:$B$1502=_xlfn.SINGLE(Spkrs[Speaker]),"N/A"))} -> SAU_2022_Speaker14_childhood_womenswork, SAU_2022_Speaker14_houses_education, SAU_2022_Speaker14_education_2, SAU_2022_Speaker14_childhood, SAU_2022_Speaker14_weddings_2, SAU_2022_Speaker14_weddings_1, SAU_2022_Speaker14_education_girls_1, SAU_2022_Speaker14_education_girls_2, SAU_2022_Speaker14_education_girls_3_driving, SAU_2022_Speaker14_Weaving_1, SAU_2022_Speaker14_Weaving_weddings, SAU_2022_Speaker14_5, SAU_2022_Speaker14_6, SAU_2022_Speaker14_7, SAU_2022_Speaker14_8, SAU_2022_Speaker14_9, SAU_2022_Speaker14_10, SAU_2022_Speaker14_11, SAU_2022_Speaker14_12, SAU_2022_Speaker14_15, SAU_2022_Speaker14_16, SAU_2022_Speaker14_17, SAU_2022_Speaker14_Weaving_4, SAU_2022_Speaker14_coffee_women, SAU_2022_Speaker14_conversationWomen | K8: Rašāyda
A9: SAU_2022_SpeakerUnknown | B9: NO | C9: F | E9: 20s | H9: Saudi Arabia | I9: seems to be a daughter of SAU_2022_Speaker14, no information or consent from her | J9: {=_xlfn.TEXTJOIN(", ",TRUE(),_xlfn._xlws.FILTER(Speakers_in_Recordings!$A$2:$A$1502,Speakers_in_Recordings!$B$2:$B$1502=_xlfn.SINGLE(Spkrs[Speaker]),"N/A"))} -> SAU_2022_Speaker14_houses_education, SAU_2022_Speaker14_education_2, SAU_2022_Speaker14_weddings_2, SAU_2022_Speaker14_weddings_1
A10: SAU_2022_Gunda | B10: YES | E10: 20s | J10: {=_xlfn.TEXTJOIN(", ",TRUE(),_xlfn._xlws.FILTER(Speakers_in_Recordings!$A$2:$A$1502,Speakers_in_Recordings!$B$2:$B$1502=_xlfn.SINGLE(Spkrs[Speaker]),"N/A"))} -> SAU_2022_Speaker10_marriage_1, SAU_2022_Speaker20_traditionalaccessories, SAU_2022_Speaker20_traditionalkitchen, SAU_2022_Speaker20_moretraditionalthings, SAU_2022_Speaker14_childhood_womenswork, SAU_2022_Speaker14_houses_education, SAU_2022_Speaker14_education_2, SAU_2022_Speaker14_childhood, SAU_2022_Speaker14_weddings_2, SAU_2022_Speaker14_weddings_1, SAU_2022_Speaker14_education_girls_1, SAU_2022_Speaker14_education_girls_2, SAU_2022_Speaker14_education_girls_3_driving, SAU_2022_Speaker10_marriage_2, SAU_2022_Speaker19_market, SAU_2022_Speaker47_games_pets, SAU_2022_Speaker37_childhood, SAU_2022_Speaker37_childhood2_marriage, SAU_2022_Speaker37_camel, SAU_2022_Speaker37_food_3eyb_haram, SAU_2022_Speaker37_3eyb_haram_2, SAU_2022_Speaker37_henna, SAU_2022_Speaker14_Weaving_1, SAU_2022_Speaker14_Weaving_weddings, SAU_2022_Speaker44_falcons_1, SAU_2022_Speaker44_falcons_2, SAU_2022_Speaker28_conversation_Oldman_1, SAU_2022_Speaker28_conversation_Oldman_2, SAU_2022_Speaker28_conversation_Oldman_3, SAU_2022_Speaker28_conversation_Oldman_4, SAU_2022_Speaker28_conversation_Oldman_5
A11: SAU_2022_DaughterofSheikh2 | B11: NO | C11: F | E11: 20s | H11: Saudi Arabia | I11: daughter of SAU_2022_Speaker9, no consent | J11: {=_xlfn.TEXTJOIN(", ",TRUE(),_xlfn._xlws.FILTER(Speakers_in_Recordings!$A$2:$A$1502,Speakers_in_Recordings!$B$2:$B$1502=_xlfn.SINGLE(Spkrs[Speaker]),"N/A"))} -> SAU_2022_Speaker47_games_pets | K11: Rašāyda
A12: SAU_2022_Speaker34 | B12: NO | C12: F | E12: 40s | H12: Saudi Arabia | I12: wife of SAU_2022_Speaker 9 and mother of _DaughterSheikh1/2, no consent | J12: {=_xlfn.TEXTJOIN(", ",TRUE(),_xlfn._xlws.FILTER(Speakers_in_Recordings!$A$2:$A$1502,Speakers_in_Recordings!$B$2:$B$1502=_xlfn.SINGLE(Spkrs[Speaker]),"N/A"))} -> SAU_2022_Speaker47_games_pets | K12: Rašāyda
A13: SAU_2022_Speaker37 | B13: YES | C13: F | D13: 1950 | E13: 70s | H13: Saudi Arabia | I13: Rašāyda, ʕArʕar | J13: {=_xlfn.TEXTJOIN(", ",TRUE(),_xlfn._xlws.FILTER(Speakers_in_Recordings!$A$2:$A$1502,Speakers_in_Recordings!$B$2:$B$1502=_xlfn.SINGLE(Spkrs[Speaker]),"N/A"))} -> SAU_2022_Speaker37_childhood, SAU_2022_Speaker37_childhood2_marriage, SAU_2022_Speaker37_camel, SAU_2022_Speaker37_food_3eyb_haram, SAU_2022_Speaker37_3eyb_haram_2, SAU_2022_Speaker37_henna | K13: Rašāyda
A14: SAU_2022_Speaker23 | B14: NO | C14: F | D14: 1990 | E14: 30s | H14: Saudi Arabia | I14: Daughter of SAU_2022_Speaker37 | J14: {=_xlfn.TEXTJOIN(", ",TRUE(),_xlfn._xlws.FILTER(Speakers_in_Recordings!$A$2:$A$1502,Speakers_in_Recordings!$B$2:$B$1502=_xlfn.SINGLE(Spkrs[Speaker]),"N/A"))} -> SAU_2022_Speaker37_childhood, SAU_2022_Speaker37_childhood2_marriage, SAU_2022_Speaker37_camel, SAU_2022_Speaker37_food_3eyb_haram, SAU_2022_Speaker37_3eyb_haram_2, SAU_2022_Speaker37_henna | K14: Rašāyda
A15: SAU_2022_Speaker16 | B15: NO | C15: F | D15: 1980 | E15: 40s | H15: Saudi Arabia | I15: Sister of SAU_2022_Speaker14; estimated birth year. Very modern woman , but aware of traditions. Knows very well how to roast coffee and showed me how to do it while also explaining some traditional dishes. Gunda has photos and a video, she wears a modern interpretation of the Niqab for the photos. | J15: {=_xlfn.TEXTJOIN(", ",TRUE(),_xlfn._xlws.FILTER(Speakers_in_Recordings!$A$2:$A$1502,Speakers_in_Recordings!$B$2:$B$1502=_xlfn.SINGLE(Spkrs[Speaker]),"N/A"))} -> SAU_2022_Speaker14_Weaving_1, SAU_2022_Speaker14_Weaving_weddings | K15: Rašāyda
A16: SAU_2022_Weaver1 | B16: NO | C16: F | E16: 70s | H16: Saudi Arabia | I16: Two old ladies were invited to the house to show us traditional weaving. They are paid by the government to give workshops on this and also sell what they make. They expect to be paid for showing their craft and are proud of being licensed by the government. | J16: {=_xlfn.TEXTJOIN(", ",TRUE(),_xlfn._xlws.FILTER(Speakers_in_Recordings!$A$2:$A$1502,Speakers_in_Recordings!$B$2:$B$1502=_xlfn.SINGLE(Spkrs[Speaker]),"N/A"))} -> SAU_2022_Speaker14_Weaving_1, SAU_2022_Speaker14_Weaving_weddings
A17: SAU_2022_Weaver2 | B17: NO | C17: F | E17: 70s | H17: Saudi Arabia | I17: Two old ladies were invited to the house to show us traditional weaving. They are paid by the government to give workshops on this and also sell what they make. They expect to be paid for showing their craft and are proud of being licensed by the government. | J17: {=_xlfn.TEXTJOIN(", ",TRUE(),_xlfn._xlws.FILTER(Speakers_in_Recordings!$A$2:$A$1502,Speakers_in_Recordings!$B$2:$B$1502=_xlfn.SINGLE(Spkrs[Speaker]),"N/A"))} -> SAU_2022_Speaker14_Weaving_weddings
A18: SAU_2022_Speaker22 | B18: YES | C18: M | D18: 1980 | E18: 40s | H18: Saudi Arabia | I18: tourguide affiliated with a ministry | J18: {=_xlfn.TEXTJOIN(", ",TRUE(),_xlfn._xlws.FILTER(Speakers_in_Recordings!$A$2:$A$1502,Speakers_in_Recordings!$B$2:$B$1502=_xlfn.SINGLE(Spkrs[Speaker]),"N/A"))} -> SAU_2022_Speaker22_narrative_historyofBaniKhaled, SAU_2022_Speaker22_rashaydasudan, SAU_2022_Speaker22_informationaboutpoets, SAU_2022_Speaker22_prophetSaleh | K18: Bani Xāled
A19: SAU_2022_Speaker46 | B19: YES | C19: M | D19: 1975 | E19: 50s | H19: Saudi Arabia | I19: brother of SAU_2022_Speaker22, also tourguide | J19: {=_xlfn.TEXTJOIN(", ",TRUE(),_xlfn._xlws.FILTER(Speakers_in_Recordings!$A$2:$A$1502,Speakers_in_Recordings!$B$2:$B$1502=_xlfn.SINGLE(Spkrs[Speaker]),"N/A"))} -> SAU_2022_Speaker46_history | K19: Bani Xāled
A20: SAU_2022_Speaker12 | B20: YES | C20: M | D20: 1970 | E20: 50s | H20: Saudi Arabia | I20: poet and owner of multiple stables | J20: {=_xlfn.TEXTJOIN(", ",TRUE(),_xlfn._xlws.FILTER(Speakers_in_Recordings!$A$2:$A$1502,Speakers_in_Recordings!$B$2:$B$1502=_xlfn.SINGLE(Spkrs[Speaker]),"N/A"))} -> SAU_2022_Speaker12_poem, SAU_2022_Speaker12_praise, SAU_2022_Speaker12_song | K20: Rašāyda | N20: high
A21: SAU_2022_Speaker42 | B21: YES | C21: M | E21: 50s | F21: no information | H21: Saudi Arabia | I21: poet | J21: {=_xlfn.TEXTJOIN(", ",TRUE(),_xlfn._xlws.FILTER(Speakers_in_Recordings!$A$2:$A$1502,Speakers_in_Recordings!$B$2:$B$1502=_xlfn.SINGLE(Spkrs[Speaker]),"N/A"))} -> SAU_2022_Speaker42_qasida | K21: Rašāyda | N21: high school
A22: SAU_2022_Speaker8 | B22: YES | C22: F | D22: 1990 | E22: 30s | H22: Saudi Arabia | I22: doctor of literature | J22: {=_xlfn.TEXTJOIN(", ",TRUE(),_xlfn._xlws.FILTER(Speakers_in_Recordings!$A$2:$A$1502,Speakers_in_Recordings!$B$2:$B$1502=_xlfn.SINGLE(Spkrs[Speaker]),"N/A"))} -> SAU_2022_Speaker8_conversationWomen_1, SAU_2022_Speaker8_conversationWomen_2, SAU_2022_Speaker8_conversationWomen_3 | K22: Rašāyda | N22: doctorate
A23: SAU_2022_Speaker6 | B23: YES | C23: M | D23: 1990 | E23: 30s | F23: estimated birth year | H23: Saudi Arabia | I23: doctor, affiliated with the ministry | J23: {=_xlfn.TEXTJOIN(", ",TRUE(),_xlfn._xlws.FILTER(Speakers_in_Recordings!$A$2:$A$1502,Speakers_in_Recordings!$B$2:$B$1502=_xlfn.SINGLE(Spkrs[Speaker]),"N/A"))} -> SAU_2022_Speaker6_conversation_dialect | K23: Rašāyda | N23: doctorate
A24: SAU_2022_Speaker47 | B24: YES | C24: F | D24: 2000 | E24: 20s | F24: estimated birth year | H24: Saudi Arabia | I24: in university, daughter of SAU_2022_Speaker9 | J24: {=_xlfn.TEXTJOIN(", ",TRUE(),_xlfn._xlws.FILTER(Speakers_in_Recordings!$A$2:$A$1502,Speakers_in_Recordings!$B$2:$B$1502=_xlfn.SINGLE(Spkrs[Speaker]),"N/A"))} -> SAU_2022_Speaker47_games_pets, SAU_2022_Speaker9_family_school | K24: Rašāyda | N24: in university
A25: SAU_2022_Speaker25 | B25: YES | C25: M | E25: 30s | H25: Saudi Arabia | I25: poet, very well travelled | J25: {=_xlfn.TEXTJOIN(", ",TRUE(),_xlfn._xlws.FILTER(Speakers_in_Recordings!$A$2:$A$1502,Speakers_in_Recordings!$B$2:$B$1502=_xlfn.SINGLE(Spkrs[Speaker]),"N/A"))} -> SAU_2022_Speaker25_poetry_recital | K25: Rašāyda | N25: seems to be highly educated
A26: SAU_2022_Speaker43 | B26: YES | C26: M | E26: 60s | H26: Saudi Arabia | I26: business man | J26: {=_xlfn.TEXTJOIN(", ",TRUE(),_xlfn._xlws.FILTER(Speakers_in_Recordings!$A$2:$A$1502,Speakers_in_Recordings!$B$2:$B$1502=_xlfn.SINGLE(Spkrs[Speaker]),"N/A"))} -> SAU_2022_Speaker43_tribe_abs, SAU_2022_Speaker43_conversation | K26: Rašāyda | N26: seems to be highly educated
A27: SAU_2022_Speaker24 | B27: YES | C27: M | D27: 1960 | E27: 60s | F27: estimated birth year | H27: Saudi Arabia | J27: {=_xlfn.TEXTJOIN(", ",TRUE(),_xlfn._xlws.FILTER(Speakers_in_Recordings!$A$2:$A$1502,Speakers_in_Recordings!$B$2:$B$1502=_xlfn.SINGLE(Spkrs[Speaker]),"N/A"))} -> SAU_2022_Speaker24_qasida_reading | K27: Rašāyda
A28: SAU_2022_Speaker28 | B28: YES | C28: M | D28: 1942 | E28: 80s | F28: estimated birth year | H28: Saudi Arabia | I28: used to be a nomad, now lives in Khaybar apparently, multiple wives, has 20 living children and about 5 dead ones. he is a poet but very humble about it | J28: {=_xlfn.TEXTJOIN(", ",TRUE(),_xlfn._xlws.FILTER(Speakers_in_Recordings!$A$2:$A$1502,Speakers_in_Recordings!$B$2:$B$1502=_xlfn.SINGLE(Spkrs[Speaker]),"N/A"))} -> SAU_2022_Speaker28_conversation_Oldman, SAU_2022_Speaker28_conversation_Oldman_1, SAU_2022_Speaker28_conversation_Oldman_2, SAU_2022_Speaker28_conversation_Oldman_3, SAU_2022_Speaker28_conversation_Oldman_4, SAU_2022_Speaker28_conversation_Oldman_5 | K28: Rašāyda
A29: SAU_2022_Speaker29 | B29: YES | C29: M | D29: 1960 | E29: 60s | F29: estimated birth year | H29: Saudi Arabia | J29: {=_xlfn.TEXTJOIN(", ",TRUE(),_xlfn._xlws.FILTER(Speakers_in_Recordings!$A$2:$A$1502,Speakers_in_Recordings!$B$2:$B$1502=_xlfn.SINGLE(Spkrs[Speaker]),"N/A"))} -> SAU_2022_Speaker29_interviews_1 | K29: Rašāyda
A30: SAU_2022_Speaker21 | B30: YES | C30: M | D30: 1959 | E30: 60s | H30: Saudi Arabia | I30: used to be a soldier | J30: {=_xlfn.TEXTJOIN(", ",TRUE(),_xlfn._xlws.FILTER(Speakers_in_Recordings!$A$2:$A$1502,Speakers_in_Recordings!$B$2:$B$1502=_xlfn.SINGLE(Spkrs[Speaker]),"N/A"))} -> SAU_2022_Speaker21_interviews | K30: Rašāyda
A31: SAU_2022_Speaker50 | B31: YES | C31: M | D31: 1955 | E31: 70s | F31: estimated birth year | H31: Saudi Arabia | J31: {=_xlfn.TEXTJOIN(", ",TRUE(),_xlfn._xlws.FILTER(Speakers_in_Recordings!$A$2:$A$1502,Speakers_in_Recordings!$B$2:$B$1502=_xlfn.SINGLE(Spkrs[Speaker]),"N/A"))} -> SAU_2022_Speaker50_interviews | K31: Rašāyda | N31: do not think he has received education- not sure though
A32: SAU_2022_Speaker51 | B32: YES | C32: M | D32: 1955 | E32: 70s | F32: estimated birth year | H32: Saudi Arabia | J32: {=_xlfn.TEXTJOIN(", ",TRUE(),_xlfn._xlws.FILTER(Speakers_in_Recordings!$A$2:$A$1502,Speakers_in_Recordings!$B$2:$B$1502=_xlfn.SINGLE(Spkrs[Speaker]),"N/A"))} -> SAU_2022_Speaker51_interviews | K32: Rašāyda
A33: SAU_2022_Speaker35 | B33: YES | C33: M | D33: 1950 | E33: 70s | F33: estimated birth year | H33: Saudi Arabia | J33: {=_xlfn.TEXTJOIN(", ",TRUE(),_xlfn._xlws.FILTER(Speakers_in_Recordings!$A$2:$A$1502,Speakers_in_Recordings!$B$2:$B$1502=_xlfn.SINGLE(Spkrs[Speaker]),"N/A"))} -> SAU_2022_Speaker35_narrativeInt_oldMan | K33: Rašāyda
A34: SAU_2022_Speaker32 | B34: YES | C34: M | D34: 1950 | E34: 70s | F34: estimated birth year | H34: Saudi Arabia | I34: from the hijazi region and seems to be very proud of this- he identifies the Rashayda as being hijazi | J34: {=_xlfn.TEXTJOIN(", ",TRUE(),_xlfn._xlws.FILTER(Speakers_in_Recordings!$A$2:$A$1502,Speakers_in_Recordings!$B$2:$B$1502=_xlfn.SINGLE(Spkrs[Speaker]),"N/A"))} -> SAU_2022_Speaker32_traditions_1 | K34: Rašāyda
A35: SAU_2022_Speaker44 | B35: YES | C35: M | D35: 1950 | E35: 70s | F35: estimated birth year | H35: Saudi Arabia | I35: raises falcons | J35: {=_xlfn.TEXTJOIN(", ",TRUE(),_xlfn._xlws.FILTER(Speakers_in_Recordings!$A$2:$A$1502,Speakers_in_Recordings!$B$2:$B$1502=_xlfn.SINGLE(Spkrs[Speaker]),"N/A"))} -> SAU_2022_Speaker44_falcons_1, SAU_2022_Speaker44_falcons_2 | K35: Rašāyda
A36: SAU_2022_Speaker49 | B36: YES | C36: M | E36: 60s | H36: Saudi Arabia | J36: {=_xlfn.TEXTJOIN(", ",TRUE(),_xlfn._xlws.FILTER(Speakers_in_Recordings!$A$2:$A$1502,Speakers_in_Recordings!$B$2:$B$1502=_xlfn.SINGLE(Spkrs[Speaker]),"N/A"))} -> SAU_2022_Speaker49_OldMan_2 | K36: Rašāyda
A37: SAU_2022_Speaker1 | B37: NO | C37: M | E37: 60s | H37: Saudi Arabia | I37: rawi for the tribe | J37: {=_xlfn.TEXTJOIN(", ",TRUE(),_xlfn._xlws.FILTER(Speakers_in_Recordings!$A$2:$A$1502,Speakers_in_Recordings!$B$2:$B$1502=_xlfn.SINGLE(Spkrs[Speaker]),"N/A"))} -> SAU_2022_Speaker28_conversation_Oldman_1, SAU_2022_Speaker28_conversation_Oldman_2, SAU_2022_Speaker28_conversation_Oldman_3, SAU_2022_Speaker28_conversation_Oldman_4, SAU_2022_Speaker28_conversation_Oldman_5 | K37: Rašāyda | N37: educated in order to be a rawi
J38: {=_xlfn.TEXTJOIN(", ",TRUE(),_xlfn._xlws.FILTER(#REF!,#REF!=_xlfn.SINGLE(Spkrs[Speaker]),"N/A"))} -> #REF!
A39: KUW_2022_Speaker8 | B39: YES | C39: F | D39: 1980 | E39: 40s | H39: Kuwait | J39: {=_xlfn.TEXTJOIN(", ",TRUE(),_xlfn._xlws.FILTER(Speakers_in_Recordings!$A$2:$A$1502,Speakers_in_Recordings!$B$2:$B$1502=_xlfn.SINGLE(Spkrs[Speaker]),"N/A"))} -> KUW_2022_Speaker8_neighbourhood, KUW_2022_Speaker8_education, KUW_2022_Speaker8_family, KUW_2022_Speaker8_wedding, KUW_2022_Speaker8_lifedevelopments_cooking, KUW_2022_Speaker8_war_goodandbadexperiences_differenceswithinrashayda, KUW_2022_Speaker8_Elicitations_PictureStories, KUW_2022_Speaker8_Elicitations_TopologicalRelations, KUW_2022_Speaker8_Elicitations_PictureStories_2, KUW_2022_Speaker8_coffeetraditions, KUW_2022_Speaker8_cooking, KUW_2022_Speaker8_traditionalmarket_recipe | K39: Rašāyda
A40: KUW_2022_Speaker12 | B40: YES | C40: M | D40: 1940 | E40: 80s | H40: Kuwait | J40: {=_xlfn.TEXTJOIN(", ",TRUE(),_xlfn._xlws.FILTER(Speakers_in_Recordings!$A$2:$A$1502,Speakers_in_Recordings!$B$2:$B$1502=_xlfn.SINGLE(Spkrs[Speaker]),"N/A"))} -> KUW_2022_Speaker12_childhood_1, KUW_2022_Speaker12_childhood_2, KUW_2022_Speaker12_childhood_3, KUW_2022_Speaker12_childhood_4, KUW_2022_Speaker12_childhood_5, KUW_2022_Speaker12_childhood_full | K40: Rašāyda
...

Sheet Campaigns
A1: Campaign | B1: ID | C1: Placename | D1: Note | E1: Type | F1: From | G1: To
A2: Al-Ula Fieldwork Campaign Ana Iriarte Diez and Stephan Procházka 2025 | B2: SAU_2025_AID_SP | C2: Saudi Arabia | E2: campaign
A3: Lebanon Fieldwork Campaign Ana Iriarte Diez 2023 | B3: LEB_2023_AID | C3: Lebanon | E3: campaign | F3: 45057 | G3: 45077
A4: Lebanon Fieldwork Campaign Ana Iriarte Diez 2022 | B4: LEB_2022_AID | C4: Lebanon | E4: campaign | F4: 44614 | G4: 44638
